Workbook

Sheet README
A1: 01 README
A3: Project | B3: Corporate Treasury & Liquidity Optimisation Engine
A4: Company | B4: Unilever plc
A5: Step | B5: Step 2 — Historical Financial Engine
A6: Purpose | B6: This workbook transforms the validated public-data source dataset into a formula-driven historical financial model covering 2021–2025 where data is available and comparable. The model establishes the historical profitability, liquidity, cash-flow, financing and working-capital base required for subsequent treasury forecasting and optimisation.
A7: Units | B7: € million unless otherwise stated.
A8: Source hierarchy | B8: 1. Unilever Annual Reports 2. Unilever Consolidated Financial Statements 3. Derived calculations 4. Explicit modelling assumptions
A9: Data classification | B9: Reported · Derived · Assumption · Unavailable
A10: Critical modelling rule | B10: No confidential Unilever treasury information is assumed. Weekly cash-flow timing, internal cash-pool pricing, internal minimum cash buffers and other non-public treasury information will be constructed only in later modelling stages and explicitly labelled as assumptions.
A11: Source file (frozen) | B11: Unilever_Treasury_FINAL_CLEAN_RAW_DATASET_v4.xlsx — never overwritten. RAW_DATA is a controlled copy of it; each row cites the dataset sheet and row.
A12: Model status | B12: =HISTORICAL_CHECKS!$B$10 -> COMPLETE — all core checks PASS
A13: Source reconciliation | B13: Completed on the v4 dataset: every input used by a core check was traced to an official Unilever document (results announcements FY2022, FY2023, FY2025; Historical Financials excl. Ice Cream; Form 20-F 2025 XBRL). Remaining blanks are line-item detail not needed by any core check; each is documented in the dataset's Source Pass Log.
A14: Period columns | B14: 2021 · 2022 · 2023 Original · 2023 Continuing · 2024 · 2025. 2023 appears twice because the 2025 Annual Report re-presented 2023–2024 for the Ice Cream demerger. Growth rates compare like with like: 2023 Original vs 2022, 2024 vs 2023 Continuing. Balance sheets are not re-presented, so balance-sheet rows have no 2023 Continuing value (grey).
A15: Basis-break warning | B15: 2021–2023 Original include Ice Cream; 2023 Continuing–2025 exclude it. 2021→2025 comparisons and CAGRs are reported-basis, not like-for-like, and are labelled accordingly.
A16: Colour legend | B16: Blue = hard-coded source value (RAW_DATA only) · Green = link to another sheet · Black = calculation · Yellow fill = Unavailable in source (enter value in RAW_DATA) · Grey fill = not applicable.
A17: How to add missing data | B17: Type the reported figure into the yellow cell on RAW_DATA (and into the frozen dataset's next version). Everything downstream, including the checks, updates automatically.
A18: Sheets | B18: 01 README · 02 RAW_DATA (input layer) · 03 HISTORICAL_IS · 04 HISTORICAL_BS · 05 HISTORICAL_CF · 06 WORKING_CAPITAL · 07 HISTORICAL_CHECKS · 08 HISTORICAL_OUTPUTS (the only sheet designed for reading).
A19: Out of scope for Step 2 | B19: 13-week forecast, weekly timing, minimum cash buffer, funding/debt/FX optimisation, investment allocation, Monte Carlo, scenarios, stress tests, live market rates, treasury policy assumptions, final dashboard and report.

Sheet RAW_DATA
A1: 02 RAW_DATA — CONTROLLED COPY OF SOURCE DATA (INPUT LAYER)
A2: Values copied unchanged from the frozen source file Unilever_Treasury_FINAL_CLEAN_RAW_DATASET_v4.xlsx. No calculations on this sheet. Blank yellow = Unavailable in source; grey = not applicable (balance sheets are not re-presented, so no 2023 Continuing).
A4: Variable | B4: 2021 | C4: 2022 | D4: 2023 Original | E4: 2023 Continuing | F4: 2024 | G4: 2025 | H4: Status | I4: Source | J4: Note
A5: INCOME STATEMENT
A6: Turnover | B6: 52444 | C6: 60073 | D6: 59604 | E6: 51680 | F6: 52479 | G6: 50503 | H6: Reported | I6: AR2022; AR2023; AR2025 | dataset: Raw Financials r6 | J6: 2023 Original vs Continuing kept separate.
A7: Cost of sales | B7: 30259 | C7: 35906 | D7: 34429 | E7: 29180 | F7: 27976 | G7: 26794 | H7: Reported | I7: AR2022; AR2023; AR2025 | dataset: Raw Financials r7 | J7: Positive = cost.
A8: Operating profit | B8: 8702 | C8: 10755 | D8: 9758 | E8: 8998 | F8: 8829 | G8: 9037 | H8: Reported | I8: AR2022; AR2023; AR2025 | dataset: Raw Financials r8
A9: Net finance costs | B9: 354 | C9: 493 | D9: 486 | E9: 408 | F9: 520 | G9: 503 | H9: Reported | I9: FY22 results (9 Feb 2023) p.15; FY23 results (8 Feb 2024) p.18; Historical Financials excl. Ice Cream (15 Jan 2026); FY25 results (12 Feb 2026) p.20 | dataset: Raw Financials r9 | J9: Positive = net cost. v4 CORRECTION: 2023 Original 409 → 486 (FY23 results p.18); 2023 Continuing 409 → 408 (excl.-Ice-Cream document). Both corrections make the PBT bridge reconcile exactly.
A10: Net monetary gain/(loss) arising from hyperinflationary economies | B10: -74 | C10: -157 | D10: -142 | E10: -169 | F10: -201 | G10: -68 | H10: Reported | I10: FY22 results (9 Feb 2023) p.15; FY23 results (8 Feb 2024) p.18; Historical Financials excl. Ice Cream (15 Jan 2026); FY25 results (12 Feb 2026) p.20 | dataset: Raw Financials r10 | J10: v4 NEW ROW. Negative = loss. Sits between operating profit and PBT; was missing from v1–v3.
A11: Share of net profit/(loss) of joint ventures and associates | B11: 191 | C11: 208 | D11: 231 | E11: 228 | F11: 250 | G11: 245 | H11: Reported | I11: FY22 results (9 Feb 2023) p.15; FY23 results (8 Feb 2024) p.18; Historical Financials excl. Ice Cream (15 Jan 2026); FY25 results (12 Feb 2026) p.20 | dataset: Raw Financials r11 | J11: Positive = income.
A12: Other income/(loss) from non-current investments and associates | B12: 91 | C12: 24 | D12: -22 | E12: -22 | F12: 13 | G12: -17 | H12: Reported | I12: FY22 results (9 Feb 2023) p.15; FY23 results (8 Feb 2024) p.18; Historical Financials excl. Ice Cream (15 Jan 2026); FY25 results (12 Feb 2026) p.20 | dataset: Raw Financials r12 | J12: Positive = income.
A13: Profit before taxation | B13: 8556 | C13: 10337 | D13: 9339 | E13: 8627 | F13: 8371 | G13: 8693 | H13: Reported | I13: FY22 results (9 Feb 2023) p.15; FY23 results (8 Feb 2024) p.18; Historical Financials excl. Ice Cream (15 Jan 2026); FY25 results (12 Feb 2026) p.20 | dataset: Raw Financials r13 | J13: 2021–2023 Original added in v4.
A14: Taxation | B14: 1935 | C14: 2068 | D14: 2199 | E14: 1990 | F14: 2332 | G14: 2481 | H14: Reported | I14: AR2022; AR2023; AR2025 (2023C via v2) | dataset: Raw Financials r14 | J14: Positive = tax charge.
A15: Net profit | B15: 6621 | C15: 8269 | D15: 7140 | E15: 6637 | F15: 6039 | G15: 6213 | H15: Reported | I15: AR2022; AR2023; AR2025 | dataset: Raw Financials r15 | J15: 2021–2023 Original: total group net profit. 2023 Continuing–2025: net profit from continuing operations.
A16: BALANCE SHEET — OPERATING ITEMS (year-end)
A17: Inventories | B17: 4683 | C17: 5931 | D17: 5119 | F17: 5177 | G17: 4043 | H17: Reported | I17: AR2022; AR2023/24; AR2025 | dataset: Raw Working Capital r6
A18: Trade receivables | B18: 3582 | C18: 4544 | D18: 4023 | F18: 4227 | G18: 4852 | H18: Reported | I18: AR2022; AR2023/24; AR2025 (Note 13) | dataset: Raw Working Capital r7
A19: Total current trade and other receivables | B19: 5422 | C19: 7056 | D19: 5775 | F19: 6011 | G19: 7346 | H19: Reported | I19: AR2022; AR2023/24; AR2025 (Note 13) | dataset: Raw Working Capital r8 | J19: Other current receivables = total − trade receivables (derive in model, not here).
A20: Trade payables | B20: 8896 | C20: 11100 | D20: 10355 | F20: 10258 | G20: 10994 | H20: Reported | I20: AR2022; AR2023/24; AR2025 (Note 14) | dataset: Raw Working Capital r10
A21: Accruals | B21: 4429 | C21: 5232 | D21: 5057 | F21: 5053 | G21: 4649 | H21: Reported | I21: AR2022; AR2023/24; AR2025 (Note 14) | dataset: Raw Working Capital r11
A22: Total trade payables and other current liabilities | B22: 14861 | C22: 18023 | D22: 16857 | F22: 16690 | G22: 16939 | H22: Reported | I22: AR2022; AR2023/24; AR2025 (Note 14) | dataset: Raw Working Capital r12 | J22: Other current operating liabilities = total − trade payables − accruals (derive in model).
A23: BALANCE SHEET — CASH, FINANCIAL ASSETS AND NET DEBT (year-end)
A24: Cash and cash equivalents — balance sheet | B24: 3415 | C24: 4326 | D24: 4159 | F24: 6136 | G24: 3941 | H24: Reported | I24: AR2022; AR2023; AR2025 | dataset: Raw Liquidity & Debt r6
A25: Bank overdrafts (deducted in CF-statement cash) | B25: 106 | C25: 101 | D25: 116 | F25: 180 | G25: 65 | H25: Reported | I25: FY22 results p.12; FY23 results p.15; FY25 results p.16 (net-debt table) | dataset: Raw Liquidity & Debt r7 | J25: Added in v4.
A26: Cash held for sale — reconciling adjustment as printed (brackets = deduction) | B26: -78 | C26: 0 | D26: -2 | F26: 6 | G26: 6 | H26: Reported | I26: FY22 results p.12; FY23 results p.15; FY25 results p.16 (net-debt table) | dataset: Raw Liquidity & Debt r8 | J26: Stored with the sign as printed: 2021 (78), 2022 –, 2023 (2), 2024 6, 2025 6. In every year CF cash + overdrafts + this adjustment = balance-sheet cash. The 2024/25 row is labelled 'Less:' but printed without brackets; the printed sign is kept.
A27: Other current financial assets | B27: 1156 | C27: 1435 | D27: 1731 | F27: 1330 | G27: 1121 | H27: Reported | I27: AR2022; AR2023; AR2025 | dataset: Raw Liquidity & Debt r9
A28: Non-current financial asset derivatives related to financial liabilities | B28: 52 | C28: 51 | D28: 75 | F28: 68 | G28: 140 | H28: Reported | I28: FY22 results p.12; FY23 results p.15; FY25 results p.16 (net-debt table) | dataset: Raw Liquidity & Debt r10 | J28: Added in v4. Equals the gap previously shown in the model's memo row in every year.
A29: Financial liabilities — current | B29: 7252 | C29: 5775 | D29: 5087 | F29: 6987 | G29: 2582 | H29: Reported | I29: AR2022; AR2023; AR2025 | dataset: Raw Liquidity & Debt r12
A30: Financial liabilities — non-current | B30: 22881 | C30: 23713 | D30: 24535 | F30: 25066 | G30: 25696 | H30: Reported | I30: AR2022; AR2023; AR2025 | dataset: Raw Liquidity & Debt r13
A31: Financial liabilities — total | B31: 30133 | C31: 29488 | D31: 29622 | F31: 32053 | G31: 28278 | H31: Reported | I31: AR2022; AR2023; AR2025 | dataset: Raw Liquidity & Debt r14
A32: Net debt (reported) | B32: 25510 | C32: 23676 | D32: 23657 | F32: 24519 | G32: 23076 | H32: Reported | I32: AR2022; AR2023; AR2025 net-debt reconciliation | dataset: Raw Liquidity & Debt r15
A33: FINANCIAL LIABILITIES BY CATEGORY (year-end)
A34: Bonds and other loans — total | B34: 27621 | C34: 26512 | G34: 26038 | H34: Reported (partial) | I34: AR2022; AR2025 (Note 15C) | dataset: Raw Liquidity & Debt r17 | J34: Disclosed in annual-report Note 15C (financial liabilities analysis), which could not be read in this environment; not in the results announcements. Not needed for any core check.
A35: Bank loans and overdrafts — total | B35: 402 | C35: 519 | G35: 233 | H35: Reported (partial) | I35: AR2022; AR2025 (Note 15C) | dataset: Raw Liquidity & Debt r18 | J35: Disclosed in annual-report Note 15C (financial liabilities analysis), which could not be read in this environment; not in the results announcements. Not needed for any core check.
A36: Bank loans and overdrafts — current | H36: Unavailable | I36: AR Note 15C — not extracted | dataset: Raw Liquidity & Debt r20 | J36: Disclosed in annual-report Note 15C (financial liabilities analysis), which could not be read in this environment; not in the results announcements. Not needed for any core check.
A37: Bonds and other loans — current | H37: Unavailable | I37: AR Note 15C — not extracted | dataset: Raw Liquidity & Debt r21 | J37: Disclosed in annual-report Note 15C (financial liabilities analysis), which could not be read in this environment; not in the results announcements. Not needed for any core check.
A38: Lease liabilities — current | H38: Unavailable | I38: AR Note 15C — not extracted | dataset: Raw Liquidity & Debt r22 | J38: Disclosed in annual-report Note 15C (financial liabilities analysis), which could not be read in this environment; not in the results announcements. Not needed for any core check.
A39: Derivatives — current | H39: Unavailable | I39: AR Note 15C — not extracted | dataset: Raw Liquidity & Debt r23 | J39: Disclosed in annual-report Note 15C (financial liabilities analysis), which could not be read in this environment; not in the results announcements. Not needed for any core check.
A40: Other financial liabilities — current | H40: Unavailable | I40: AR Note 15C — not extracted | dataset: Raw Liquidity & Debt r24 | J40: Disclosed in annual-report Note 15C (financial liabilities analysis), which could not be read in this environment; not in the results announcements. Not needed for any core check.
A41: Bank loans and overdrafts — non-current | H41: Unavailable | I41: AR Note 15C — not extracted | dataset: Raw Liquidity & Debt r26 | J41: Disclosed in annual-report Note 15C (financial liabilities analysis), which could not be read in this environment; not in the results announcements. Not needed for any core check.
...

Sheet HISTORICAL_IS
A1: 03 HISTORICAL_IS — INCOME STATEMENT ENGINE
A2: € million. Costs are shown as positive numbers (as reported in the source). Green = link to RAW_DATA; black = calculation.
A4: €m | B4: 2021 | C4: 2022 | D4: 2023 Original | E4: 2023 Continuing | F4: 2024 | G4: 2025 | H4: Notes
A5: A. Input lines (linked to RAW_DATA)
A6: Turnover | B6: =IF(RAW_DATA!B6="","",RAW_DATA!B6) -> 52444 | C6: =IF(RAW_DATA!C6="","",RAW_DATA!C6) -> 60073 | D6: =IF(RAW_DATA!D6="","",RAW_DATA!D6) -> 59604 | E6: =IF(RAW_DATA!E6="","",RAW_DATA!E6) -> 51680 | F6: =IF(RAW_DATA!F6="","",RAW_DATA!F6) -> 52479 | G6: =IF(RAW_DATA!G6="","",RAW_DATA!G6) -> 50503
A7: Cost of sales | B7: =IF(RAW_DATA!B7="","",RAW_DATA!B7) -> 30259 | C7: =IF(RAW_DATA!C7="","",RAW_DATA!C7) -> 35906 | D7: =IF(RAW_DATA!D7="","",RAW_DATA!D7) -> 34429 | E7: =IF(RAW_DATA!E7="","",RAW_DATA!E7) -> 29180 | F7: =IF(RAW_DATA!F7="","",RAW_DATA!F7) -> 27976 | G7: =IF(RAW_DATA!G7="","",RAW_DATA!G7) -> 26794 | H7: Positive = cost.
A8: Operating profit | B8: =IF(RAW_DATA!B8="","",RAW_DATA!B8) -> 8702 | C8: =IF(RAW_DATA!C8="","",RAW_DATA!C8) -> 10755 | D8: =IF(RAW_DATA!D8="","",RAW_DATA!D8) -> 9758 | E8: =IF(RAW_DATA!E8="","",RAW_DATA!E8) -> 8998 | F8: =IF(RAW_DATA!F8="","",RAW_DATA!F8) -> 8829 | G8: =IF(RAW_DATA!G8="","",RAW_DATA!G8) -> 9037
A9: Net finance costs | B9: =IF(RAW_DATA!B9="","",RAW_DATA!B9) -> 354 | C9: =IF(RAW_DATA!C9="","",RAW_DATA!C9) -> 493 | D9: =IF(RAW_DATA!D9="","",RAW_DATA!D9) -> 486 | E9: =IF(RAW_DATA!E9="","",RAW_DATA!E9) -> 408 | F9: =IF(RAW_DATA!F9="","",RAW_DATA!F9) -> 520 | G9: =IF(RAW_DATA!G9="","",RAW_DATA!G9) -> 503 | H9: Positive = net cost.
A10: Net monetary gain/(loss) from hyperinflationary economies | B10: =IF(RAW_DATA!B10="","",RAW_DATA!B10) -> -74 | C10: =IF(RAW_DATA!C10="","",RAW_DATA!C10) -> -157 | D10: =IF(RAW_DATA!D10="","",RAW_DATA!D10) -> -142 | E10: =IF(RAW_DATA!E10="","",RAW_DATA!E10) -> -169 | F10: =IF(RAW_DATA!F10="","",RAW_DATA!F10) -> -201 | G10: =IF(RAW_DATA!G10="","",RAW_DATA!G10) -> -68 | H10: Other PBT item. Negative = loss.
A11: Share of net profit/(loss) of JVs and associates | B11: =IF(RAW_DATA!B11="","",RAW_DATA!B11) -> 191 | C11: =IF(RAW_DATA!C11="","",RAW_DATA!C11) -> 208 | D11: =IF(RAW_DATA!D11="","",RAW_DATA!D11) -> 231 | E11: =IF(RAW_DATA!E11="","",RAW_DATA!E11) -> 228 | F11: =IF(RAW_DATA!F11="","",RAW_DATA!F11) -> 250 | G11: =IF(RAW_DATA!G11="","",RAW_DATA!G11) -> 245 | H11: Other PBT item. Positive = income.
A12: Other income/(loss) from non-current investments | B12: =IF(RAW_DATA!B12="","",RAW_DATA!B12) -> 91 | C12: =IF(RAW_DATA!C12="","",RAW_DATA!C12) -> 24 | D12: =IF(RAW_DATA!D12="","",RAW_DATA!D12) -> -22 | E12: =IF(RAW_DATA!E12="","",RAW_DATA!E12) -> -22 | F12: =IF(RAW_DATA!F12="","",RAW_DATA!F12) -> 13 | G12: =IF(RAW_DATA!G12="","",RAW_DATA!G12) -> -17 | H12: Other PBT item. Positive = income.
A13: Profit before tax | B13: =IF(RAW_DATA!B13="","",RAW_DATA!B13) -> 8556 | C13: =IF(RAW_DATA!C13="","",RAW_DATA!C13) -> 10337 | D13: =IF(RAW_DATA!D13="","",RAW_DATA!D13) -> 9339 | E13: =IF(RAW_DATA!E13="","",RAW_DATA!E13) -> 8627 | F13: =IF(RAW_DATA!F13="","",RAW_DATA!F13) -> 8371 | G13: =IF(RAW_DATA!G13="","",RAW_DATA!G13) -> 8693
A14: Tax | B14: =IF(RAW_DATA!B14="","",RAW_DATA!B14) -> 1935 | C14: =IF(RAW_DATA!C14="","",RAW_DATA!C14) -> 2068 | D14: =IF(RAW_DATA!D14="","",RAW_DATA!D14) -> 2199 | E14: =IF(RAW_DATA!E14="","",RAW_DATA!E14) -> 1990 | F14: =IF(RAW_DATA!F14="","",RAW_DATA!F14) -> 2332 | G14: =IF(RAW_DATA!G14="","",RAW_DATA!G14) -> 2481 | H14: Positive = charge.
A15: Net profit | B15: =IF(RAW_DATA!B15="","",RAW_DATA!B15) -> 6621 | C15: =IF(RAW_DATA!C15="","",RAW_DATA!C15) -> 8269 | D15: =IF(RAW_DATA!D15="","",RAW_DATA!D15) -> 7140 | E15: =IF(RAW_DATA!E15="","",RAW_DATA!E15) -> 6637 | F15: =IF(RAW_DATA!F15="","",RAW_DATA!F15) -> 6039 | G15: =IF(RAW_DATA!G15="","",RAW_DATA!G15) -> 6213 | H15: 2021–2023 Original: total group net profit. 2023 Continuing–2025: continuing operations.
A16: Memo: implied other PBT items (PBT − operating profit + net finance costs) | B16: =IFERROR(B13-B8+B9,"") -> 208 | C16: =IFERROR(C13-C8+C9,"") -> 75 | D16: =IFERROR(D13-D8+D9,"") -> 67 | E16: =IFERROR(E13-E8+E9,"") -> 37 | F16: =IFERROR(F13-F8+F9,"") -> 62 | G16: =IFERROR(G13-G8+G9,"") -> 159 | H16: Diagnostic only: equals hyperinflation + JV/associate share + other income (tested in Check 1). Not used as an input.
A18: B. Income-statement calculations
A19: Revenue growth (like-for-like) | C19: =IFERROR(C6/B6-1,"") -> 0.14546945 | D19: =IFERROR(D6/C6-1,"") -> -0.0078071679 | F19: =IFERROR(F6/E6-1,"") -> 0.015460526 | G19: =IFERROR(G6/F6-1,"") -> -0.037653157 | H19: 2022 vs 2021; 2023 Original vs 2022; 2024 vs 2023 Continuing; 2025 vs 2024. No 2021 (needs 2020) and no 2023 Continuing (no re-presented 2022).
A20: Operating margin | B20: =IFERROR(B8/B6,"") -> 0.16592937 | C20: =IFERROR(C8/C6,"") -> 0.17903218 | D20: =IFERROR(D8/D6,"") -> 0.16371384 | E20: =IFERROR(E8/E6,"") -> 0.17410991 | F20: =IFERROR(F8/F6,"") -> 0.16823872 | G20: =IFERROR(G8/G6,"") -> 0.17893986
A21: Net margin | B21: =IFERROR(B15/B6,"") -> 0.12624895 | C21: =IFERROR(C15/C6,"") -> 0.13764919 | D21: =IFERROR(D15/D6,"") -> 0.11979062 | E21: =IFERROR(E15/E6,"") -> 0.12842492 | F21: =IFERROR(F15/F6,"") -> 0.1150746 | G21: =IFERROR(G15/G6,"") -> 0.12302239
A22: Effective tax rate | B22: =IFERROR(B14/B13,"") -> 0.22615708 | C22: =IFERROR(C14/C13,"") -> 0.20005804 | D22: =IFERROR(D14/D13,"") -> 0.23546418 | E22: =IFERROR(E14/E13,"") -> 0.23067115 | F22: =IFERROR(F14/F13,"") -> 0.27858081 | G22: =IFERROR(G14/G13,"") -> 0.28540205 | H22: Tax ÷ PBT. Effective, not statutory.
A23: Finance-cost ratio | B23: =IFERROR(B9/B6,"") -> 0.0067500572 | C23: =IFERROR(C9/C6,"") -> 0.0082066819 | D23: =IFERROR(D9/D6,"") -> 0.0081538152 | E23: =IFERROR(E9/E6,"") -> 0.0078947368 | F23: =IFERROR(F9/F6,"") -> 0.0099087254 | G23: =IFERROR(G9/G6,"") -> 0.0099598044 | H23: Net finance costs ÷ turnover.

Sheet HISTORICAL_BS
A1: 04 HISTORICAL_BS — TREASURY-RELEVANT BALANCE SHEET ENGINE
A2: € million, year-end. 2023 Continuing column is not applicable (balance sheets are not re-presented); the 2023 year-end sits in 2023 Original.
A4: €m | B4: 2021 | C4: 2022 | D4: 2023 Original | E4: 2023 Continuing | F4: 2024 | G4: 2025 | H4: Notes
A5: A. Operating assets
A6: Inventories | B6: =IF(RAW_DATA!B17="","",RAW_DATA!B17) -> 4683 | C6: =IF(RAW_DATA!C17="","",RAW_DATA!C17) -> 5931 | D6: =IF(RAW_DATA!D17="","",RAW_DATA!D17) -> 5119 | F6: =IF(RAW_DATA!F17="","",RAW_DATA!F17) -> 5177 | G6: =IF(RAW_DATA!G17="","",RAW_DATA!G17) -> 4043
A7: Trade receivables | B7: =IF(RAW_DATA!B18="","",RAW_DATA!B18) -> 3582 | C7: =IF(RAW_DATA!C18="","",RAW_DATA!C18) -> 4544 | D7: =IF(RAW_DATA!D18="","",RAW_DATA!D18) -> 4023 | F7: =IF(RAW_DATA!F18="","",RAW_DATA!F18) -> 4227 | G7: =IF(RAW_DATA!G18="","",RAW_DATA!G18) -> 4852
A8: Other current receivables | B8: =IF(COUNT(RAW_DATA!B19,RAW_DATA!B18)<2,"",RAW_DATA!B19-RAW_DATA!B18) -> 1840 | C8: =IF(COUNT(RAW_DATA!C19,RAW_DATA!C18)<2,"",RAW_DATA!C19-RAW_DATA!C18) -> 2512 | D8: =IF(COUNT(RAW_DATA!D19,RAW_DATA!D18)<2,"",RAW_DATA!D19-RAW_DATA!D18) -> 1752 | F8: =IF(COUNT(RAW_DATA!F19,RAW_DATA!F18)<2,"",RAW_DATA!F19-RAW_DATA!F18) -> 1784 | G8: =IF(COUNT(RAW_DATA!G19,RAW_DATA!G18)<2,"",RAW_DATA!G19-RAW_DATA!G18) -> 2494 | H8: Derived: total current trade and other receivables − trade receivables.
A9: Total current receivables | B9: =IF(RAW_DATA!B19="","",RAW_DATA!B19) -> 5422 | C9: =IF(RAW_DATA!C19="","",RAW_DATA!C19) -> 7056 | D9: =IF(RAW_DATA!D19="","",RAW_DATA!D19) -> 5775 | F9: =IF(RAW_DATA!F19="","",RAW_DATA!F19) -> 6011 | G9: =IF(RAW_DATA!G19="","",RAW_DATA!G19) -> 7346
A11: B. Liquidity
A12: Cash & cash equivalents (balance sheet) | B12: =IF(RAW_DATA!B24="","",RAW_DATA!B24) -> 3415 | C12: =IF(RAW_DATA!C24="","",RAW_DATA!C24) -> 4326 | D12: =IF(RAW_DATA!D24="","",RAW_DATA!D24) -> 4159 | F12: =IF(RAW_DATA!F24="","",RAW_DATA!F24) -> 6136 | G12: =IF(RAW_DATA!G24="","",RAW_DATA!G24) -> 3941
A13: Other current financial assets | B13: =IF(RAW_DATA!B27="","",RAW_DATA!B27) -> 1156 | C13: =IF(RAW_DATA!C27="","",RAW_DATA!C27) -> 1435 | D13: =IF(RAW_DATA!D27="","",RAW_DATA!D27) -> 1731 | F13: =IF(RAW_DATA!F27="","",RAW_DATA!F27) -> 1330 | G13: =IF(RAW_DATA!G27="","",RAW_DATA!G27) -> 1121
A14: Total liquidity | B14: =IFERROR(B12+B13,"") -> 4571 | C14: =IFERROR(C12+C13,"") -> 5761 | D14: =IFERROR(D12+D13,"") -> 5890 | F14: =IFERROR(F12+F13,"") -> 7466 | G14: =IFERROR(G12+G13,"") -> 5062 | H14: Cash + other current financial assets. Excludes undrawn facilities; includes restricted cash.
A16: C. Cash definitions — kept separate, never combined
A17: Cash & equivalents — balance sheet | B17: =IF(RAW_DATA!B24="","",RAW_DATA!B24) -> 3415 | C17: =IF(RAW_DATA!C24="","",RAW_DATA!C24) -> 4326 | D17: =IF(RAW_DATA!D24="","",RAW_DATA!D24) -> 4159 | F17: =IF(RAW_DATA!F24="","",RAW_DATA!F24) -> 6136 | G17: =IF(RAW_DATA!G24="","",RAW_DATA!G24) -> 3941
A18: Cash & equivalents — cash-flow statement (net of overdrafts) | B18: =IF(RAW_DATA!B97="","",RAW_DATA!B97) -> 3387 | C18: =IF(RAW_DATA!C97="","",RAW_DATA!C97) -> 4225 | D18: =IF(RAW_DATA!D97="","",RAW_DATA!D97) -> 4045 | F18: =IF(RAW_DATA!F97="","",RAW_DATA!F97) -> 5950 | G18: =IF(RAW_DATA!G97="","",RAW_DATA!G97) -> 3870 | H18: Cash-flow-statement closing balance.
A19: Bank overdrafts | B19: =IF(RAW_DATA!B25="","",RAW_DATA!B25) -> 106 | C19: =IF(RAW_DATA!C25="","",RAW_DATA!C25) -> 101 | D19: =IF(RAW_DATA!D25="","",RAW_DATA!D25) -> 116 | F19: =IF(RAW_DATA!F25="","",RAW_DATA!F25) -> 180 | G19: =IF(RAW_DATA!G25="","",RAW_DATA!G25) -> 65
A20: Cash held for sale — reconciling adjustment (as printed) | B20: =IF(RAW_DATA!B26="","",RAW_DATA!B26) -> -78 | C20: =IF(RAW_DATA!C26="","",RAW_DATA!C26) -> 0 | D20: =IF(RAW_DATA!D26="","",RAW_DATA!D26) -> -2 | F20: =IF(RAW_DATA!F26="","",RAW_DATA!F26) -> 6 | G20: =IF(RAW_DATA!G26="","",RAW_DATA!G26) -> 6 | H20: Sign as printed in Unilever's net-debt table (brackets = deduction). CF cash + overdrafts + this = balance-sheet cash.
A21: Other current financial assets | B21: =IF(RAW_DATA!B27="","",RAW_DATA!B27) -> 1156 | C21: =IF(RAW_DATA!C27="","",RAW_DATA!C27) -> 1435 | D21: =IF(RAW_DATA!D27="","",RAW_DATA!D27) -> 1731 | F21: =IF(RAW_DATA!F27="","",RAW_DATA!F27) -> 1330 | G21: =IF(RAW_DATA!G27="","",RAW_DATA!G27) -> 1121
A22: Non-current financial asset derivatives related to financial liabilities | B22: =IF(RAW_DATA!B28="","",RAW_DATA!B28) -> 52 | C22: =IF(RAW_DATA!C28="","",RAW_DATA!C28) -> 51 | D22: =IF(RAW_DATA!D28="","",RAW_DATA!D28) -> 75 | F22: =IF(RAW_DATA!F28="","",RAW_DATA!F28) -> 68 | G22: =IF(RAW_DATA!G28="","",RAW_DATA!G28) -> 140
A23: Memo: balance-sheet cash − cash-flow-statement cash | B23: =IFERROR(B17-B18,"") -> 28 | C23: =IFERROR(C17-C18,"") -> 101 | D23: =IFERROR(D17-D18,"") -> 114 | F23: =IFERROR(F17-F18,"") -> 186 | G23: =IFERROR(G17-G18,"") -> 71 | H23: Equals overdrafts + held-for-sale adjustment (tested on HISTORICAL_CHECKS, S1).
A25: D. Operating liabilities
A26: Trade payables | B26: =IF(RAW_DATA!B20="","",RAW_DATA!B20) -> 8896 | C26: =IF(RAW_DATA!C20="","",RAW_DATA!C20) -> 11100 | D26: =IF(RAW_DATA!D20="","",RAW_DATA!D20) -> 10355 | F26: =IF(RAW_DATA!F20="","",RAW_DATA!F20) -> 10258 | G26: =IF(RAW_DATA!G20="","",RAW_DATA!G20) -> 10994
A27: Accruals | B27: =IF(RAW_DATA!B21="","",RAW_DATA!B21) -> 4429 | C27: =IF(RAW_DATA!C21="","",RAW_DATA!C21) -> 5232 | D27: =IF(RAW_DATA!D21="","",RAW_DATA!D21) -> 5057 | F27: =IF(RAW_DATA!F21="","",RAW_DATA!F21) -> 5053 | G27: =IF(RAW_DATA!G21="","",RAW_DATA!G21) -> 4649
A28: Other current operating liabilities | B28: =IF(COUNT(RAW_DATA!B22,RAW_DATA!B20,RAW_DATA!B21)<3,"",RAW_DATA!B22-RAW_DATA!B20-RAW_DATA!B21) -> 1536 | C28: =IF(COUNT(RAW_DATA!C22,RAW_DATA!C20,RAW_DATA!C21)<3,"",RAW_DATA!C22-RAW_DATA!C20-RAW_DATA!C21) -> 1691 | D28: =IF(COUNT(RAW_DATA!D22,RAW_DATA!D20,RAW_DATA!D21)<3,"",RAW_DATA!D22-RAW_DATA!D20-RAW_DATA!D21) -> 1445 | F28: =IF(COUNT(RAW_DATA!F22,RAW_DATA!F20,RAW_DATA!F21)<3,"",RAW_DATA!F22-RAW_DATA!F20-RAW_DATA!F21) -> 1379 | G28: =IF(COUNT(RAW_DATA!G22,RAW_DATA!G20,RAW_DATA!G21)<3,"",RAW_DATA!G22-RAW_DATA!G20-RAW_DATA!G21) -> 1296 | H28: Derived: total trade payables and other current liabilities − trade payables − accruals.
A29: Total operating liabilities | B29: =IF(RAW_DATA!B22="","",RAW_DATA!B22) -> 14861 | C29: =IF(RAW_DATA!C22="","",RAW_DATA!C22) -> 18023 | D29: =IF(RAW_DATA!D22="","",RAW_DATA!D22) -> 16857 | F29: =IF(RAW_DATA!F22="","",RAW_DATA!F22) -> 16690 | G29: =IF(RAW_DATA!G22="","",RAW_DATA!G22) -> 16939 | H29: Reported 'trade payables and other current liabilities'.
A30: Operating NWC (inventories + total current receivables − total operating liabilities) | B30: =IFERROR(B6+B9-B29,"") -> -4756 | C30: =IFERROR(C6+C9-C29,"") -> -5036 | D30: =IFERROR(D6+D9-D29,"") -> -5963 | F30: =IFERROR(F6+F9-F29,"") -> -5502 | G30: =IFERROR(G6+G9-G29,"") -> -5550 | H30: Historical base only — not used for forecasting in Step 2. Negative = operating liabilities exceed operating assets.
A32: E. Financial liabilities — current
A33: Bank loans and overdrafts | B33: =IF(RAW_DATA!B36="","",RAW_DATA!B36) | C33: =IF(RAW_DATA!C36="","",RAW_DATA!C36) | D33: =IF(RAW_DATA!D36="","",RAW_DATA!D36) | F33: =IF(RAW_DATA!F36="","",RAW_DATA!F36) | G33: =IF(RAW_DATA!G36="","",RAW_DATA!G36)
A34: Bonds and other loans | B34: =IF(RAW_DATA!B37="","",RAW_DATA!B37) | C34: =IF(RAW_DATA!C37="","",RAW_DATA!C37) | D34: =IF(RAW_DATA!D37="","",RAW_DATA!D37) | F34: =IF(RAW_DATA!F37="","",RAW_DATA!F37) | G34: =IF(RAW_DATA!G37="","",RAW_DATA!G37)
A35: Lease liabilities | B35: =IF(RAW_DATA!B38="","",RAW_DATA!B38) | C35: =IF(RAW_DATA!C38="","",RAW_DATA!C38) | D35: =IF(RAW_DATA!D38="","",RAW_DATA!D38) | F35: =IF(RAW_DATA!F38="","",RAW_DATA!F38) | G35: =IF(RAW_DATA!G38="","",RAW_DATA!G38)
A36: Derivatives | B36: =IF(RAW_DATA!B39="","",RAW_DATA!B39) | C36: =IF(RAW_DATA!C39="","",RAW_DATA!C39) | D36: =IF(RAW_DATA!D39="","",RAW_DATA!D39) | F36: =IF(RAW_DATA!F39="","",RAW_DATA!F39) | G36: =IF(RAW_DATA!G39="","",RAW_DATA!G39)
A37: Other financial liabilities | B37: =IF(RAW_DATA!B40="","",RAW_DATA!B40) | C37: =IF(RAW_DATA!C40="","",RAW_DATA!C40) | D37: =IF(RAW_DATA!D40="","",RAW_DATA!D40) | F37: =IF(RAW_DATA!F40="","",RAW_DATA!F40) | G37: =IF(RAW_DATA!G40="","",RAW_DATA!G40)
A38: Sum of current categories | B38: =IFERROR(B33+B34+B35+B36+B37,"") | C38: =IFERROR(C33+C34+C35+C36+C37,"") | D38: =IFERROR(D33+D34+D35+D36+D37,"") | F38: =IFERROR(F33+F34+F35+F36+F37,"") | G38: =IFERROR(G33+G34+G35+G36+G37,"") | H38: Blank until every category is sourced.
A39: Total current financial liabilities (reported) | B39: =IF(RAW_DATA!B29="","",RAW_DATA!B29) -> 7252 | C39: =IF(RAW_DATA!C29="","",RAW_DATA!C29) -> 5775 | D39: =IF(RAW_DATA!D29="","",RAW_DATA!D29) -> 5087 | F39: =IF(RAW_DATA!F29="","",RAW_DATA!F29) -> 6987 | G39: =IF(RAW_DATA!G29="","",RAW_DATA!G29) -> 2582
A40: E. Financial liabilities — non-current
A41: Bank loans and overdrafts | B41: =IF(RAW_DATA!B41="","",RAW_DATA!B41) | C41: =IF(RAW_DATA!C41="","",RAW_DATA!C41) | D41: =IF(RAW_DATA!D41="","",RAW_DATA!D41) | F41: =IF(RAW_DATA!F41="","",RAW_DATA!F41) | G41: =IF(RAW_DATA!G41="","",RAW_DATA!G41)
A42: Bonds and other loans | B42: =IF(RAW_DATA!B42="","",RAW_DATA!B42) | C42: =IF(RAW_DATA!C42="","",RAW_DATA!C42) | D42: =IF(RAW_DATA!D42="","",RAW_DATA!D42) | F42: =IF(RAW_DATA!F42="","",RAW_DATA!F42) | G42: =IF(RAW_DATA!G42="","",RAW_DATA!G42)
A43: Lease liabilities | B43: =IF(RAW_DATA!B43="","",RAW_DATA!B43) | C43: =IF(RAW_DATA!C43="","",RAW_DATA!C43) | D43: =IF(RAW_DATA!D43="","",RAW_DATA!D43) | F43: =IF(RAW_DATA!F43="","",RAW_DATA!F43) | G43: =IF(RAW_DATA!G43="","",RAW_DATA!G43)
A44: Derivatives | B44: =IF(RAW_DATA!B44="","",RAW_DATA!B44) | C44: =IF(RAW_DATA!C44="","",RAW_DATA!C44) | D44: =IF(RAW_DATA!D44="","",RAW_DATA!D44) | F44: =IF(RAW_DATA!F44="","",RAW_DATA!F44) | G44: =IF(RAW_DATA!G44="","",RAW_DATA!G44)
A45: Other financial liabilities | B45: =IF(RAW_DATA!B45="","",RAW_DATA!B45) | C45: =IF(RAW_DATA!C45="","",RAW_DATA!C45) | D45: =IF(RAW_DATA!D45="","",RAW_DATA!D45) | F45: =IF(RAW_DATA!F45="","",RAW_DATA!F45) | G45: =IF(RAW_DATA!G45="","",RAW_DATA!G45)
...

Sheet HISTORICAL_CF
A1: 05 HISTORICAL_CF — CASH-FLOW ENGINE
A2: € million. Inflows positive, outflows negative (as reported). 2023 Continuing–2025 on the AR2025 continuing basis.
A4: €m | B4: 2021 | C4: 2022 | D4: 2023 Original | E4: 2023 Continuing | F4: 2024 | G4: 2025 | H4: Notes
A5: A. Operating cash flow
A6: Net profit from continuing operations | B6: =IF(RAW_DATA!B47="","",RAW_DATA!B47) | C6: =IF(RAW_DATA!C47="","",RAW_DATA!C47) | D6: =IF(RAW_DATA!D47="","",RAW_DATA!D47) | E6: =IF(RAW_DATA!E47="","",RAW_DATA!E47) | F6: =IF(RAW_DATA!F47="","",RAW_DATA!F47) -> 6039 | G6: =IF(RAW_DATA!G47="","",RAW_DATA!G47) -> 6213
A7: Taxation | B7: =IF(RAW_DATA!B48="","",RAW_DATA!B48) | C7: =IF(RAW_DATA!C48="","",RAW_DATA!C48) | D7: =IF(RAW_DATA!D48="","",RAW_DATA!D48) | E7: =IF(RAW_DATA!E48="","",RAW_DATA!E48) | F7: =IF(RAW_DATA!F48="","",RAW_DATA!F48) -> 2332 | G7: =IF(RAW_DATA!G48="","",RAW_DATA!G48) -> 2481
A8: JV/associate and non-current investment income | B8: =IF(RAW_DATA!B49="","",RAW_DATA!B49) | C8: =IF(RAW_DATA!C49="","",RAW_DATA!C49) | D8: =IF(RAW_DATA!D49="","",RAW_DATA!D49) | E8: =IF(RAW_DATA!E49="","",RAW_DATA!E49) | F8: =IF(RAW_DATA!F49="","",RAW_DATA!F49) -> -263 | G8: =IF(RAW_DATA!G49="","",RAW_DATA!G49) -> -228
A9: Hyperinflationary adjustments | B9: =IF(RAW_DATA!B50="","",RAW_DATA!B50) | C9: =IF(RAW_DATA!C50="","",RAW_DATA!C50) | D9: =IF(RAW_DATA!D50="","",RAW_DATA!D50) | E9: =IF(RAW_DATA!E50="","",RAW_DATA!E50) | F9: =IF(RAW_DATA!F50="","",RAW_DATA!F50) -> 201 | G9: =IF(RAW_DATA!G50="","",RAW_DATA!G50) -> 68
A10: Net finance costs | B10: =IF(RAW_DATA!B51="","",RAW_DATA!B51) | C10: =IF(RAW_DATA!C51="","",RAW_DATA!C51) | D10: =IF(RAW_DATA!D51="","",RAW_DATA!D51) | E10: =IF(RAW_DATA!E51="","",RAW_DATA!E51) | F10: =IF(RAW_DATA!F51="","",RAW_DATA!F51) -> 520 | G10: =IF(RAW_DATA!G51="","",RAW_DATA!G51) -> 503
A11: Depreciation, amortisation and impairment | B11: =IF(RAW_DATA!B52="","",RAW_DATA!B52) | C11: =IF(RAW_DATA!C52="","",RAW_DATA!C52) | D11: =IF(RAW_DATA!D52="","",RAW_DATA!D52) | E11: =IF(RAW_DATA!E52="","",RAW_DATA!E52) -> 1148 | F11: =IF(RAW_DATA!F52="","",RAW_DATA!F52) -> 1370 | G11: =IF(RAW_DATA!G52="","",RAW_DATA!G52) -> 1353
A12: Changes in working capital | B12: =IF(RAW_DATA!B53="","",RAW_DATA!B53) | C12: =IF(RAW_DATA!C53="","",RAW_DATA!C53) | D12: =IF(RAW_DATA!D53="","",RAW_DATA!D53) | E12: =IF(RAW_DATA!E53="","",RAW_DATA!E53) -> 753 | F12: =IF(RAW_DATA!F53="","",RAW_DATA!F53) -> -188 | G12: =IF(RAW_DATA!G53="","",RAW_DATA!G53) -> 116
A13: Pensions | B13: =IF(RAW_DATA!B54="","",RAW_DATA!B54) | C13: =IF(RAW_DATA!C54="","",RAW_DATA!C54) | D13: =IF(RAW_DATA!D54="","",RAW_DATA!D54) | E13: =IF(RAW_DATA!E54="","",RAW_DATA!E54) -> -251 | F13: =IF(RAW_DATA!F54="","",RAW_DATA!F54) -> -54 | G13: =IF(RAW_DATA!G54="","",RAW_DATA!G54) -> -74
A14: Provisions | B14: =IF(RAW_DATA!B55="","",RAW_DATA!B55) | C14: =IF(RAW_DATA!C55="","",RAW_DATA!C55) | D14: =IF(RAW_DATA!D55="","",RAW_DATA!D55) | E14: =IF(RAW_DATA!E55="","",RAW_DATA!E55) -> -171 | F14: =IF(RAW_DATA!F55="","",RAW_DATA!F55) -> 289 | G14: =IF(RAW_DATA!G55="","",RAW_DATA!G55) -> -130
A15: Disposal adjustments | B15: =IF(RAW_DATA!B56="","",RAW_DATA!B56) | C15: =IF(RAW_DATA!C56="","",RAW_DATA!C56) | D15: =IF(RAW_DATA!D56="","",RAW_DATA!D56) | E15: =IF(RAW_DATA!E56="","",RAW_DATA!E56) -> -440 | F15: =IF(RAW_DATA!F56="","",RAW_DATA!F56) -> 259 | G15: =IF(RAW_DATA!G56="","",RAW_DATA!G56) -> 58
A16: Share-based compensation | B16: =IF(RAW_DATA!B57="","",RAW_DATA!B57) | C16: =IF(RAW_DATA!C57="","",RAW_DATA!C57) | D16: =IF(RAW_DATA!D57="","",RAW_DATA!D57) | E16: =IF(RAW_DATA!E57="","",RAW_DATA!E57) -> 192 | F16: =IF(RAW_DATA!F57="","",RAW_DATA!F57) -> 292 | G16: =IF(RAW_DATA!G57="","",RAW_DATA!G57) -> 255
A17: Other adjustments | B17: =IF(RAW_DATA!B58="","",RAW_DATA!B58) | C17: =IF(RAW_DATA!C58="","",RAW_DATA!C58) | D17: =IF(RAW_DATA!D58="","",RAW_DATA!D58) | E17: =IF(RAW_DATA!E58="","",RAW_DATA!E58) -> 97 | F17: =IF(RAW_DATA!F58="","",RAW_DATA!F58) -> 116 | G17: =IF(RAW_DATA!G58="","",RAW_DATA!G58) -> 157
A18: Sum of components | B18: =IFERROR(B6+B7+B8+B9+B10+B11+B12+B13+B14+B15+B16+B17,"") | C18: =IFERROR(C6+C7+C8+C9+C10+C11+C12+C13+C14+C15+C16+C17,"") | D18: =IFERROR(D6+D7+D8+D9+D10+D11+D12+D13+D14+D15+D16+D17,"") | E18: =IFERROR(E6+E7+E8+E9+E10+E11+E12+E13+E14+E15+E16+E17,"") | F18: =IFERROR(F6+F7+F8+F9+F10+F11+F12+F13+F14+F15+F16+F17,"") -> 10913 | G18: =IFERROR(G6+G7+G8+G9+G10+G11+G12+G13+G14+G15+G16+G17,"") -> 10772 | H18: Blank until every component is sourced; tested against reported operating cash flow (S4).
A19: Operating cash flow (cash flow from operating activities, before tax) | B19: =IF(RAW_DATA!B59="","",RAW_DATA!B59) -> 10305 | C19: =IF(RAW_DATA!C59="","",RAW_DATA!C59) -> 10089 | D19: =IF(RAW_DATA!D59="","",RAW_DATA!D59) -> 11561 | E19: =IF(RAW_DATA!E59="","",RAW_DATA!E59) -> 10326 | F19: =IF(RAW_DATA!F59="","",RAW_DATA!F59) -> 10913 | G19: =IF(RAW_DATA!G59="","",RAW_DATA!G59) -> 10772 | H19: Unilever's FCF starting point. 2023 Continuing–2025 are continuing operations only.
A20: Income tax paid | B20: =IF(RAW_DATA!B60="","",RAW_DATA!B60) -> -2333 | C20: =IF(RAW_DATA!C60="","",RAW_DATA!C60) -> -2807 | D20: =IF(RAW_DATA!D60="","",RAW_DATA!D60) -> -2135 | E20: =IF(RAW_DATA!E60="","",RAW_DATA!E60) -> -1933 | F20: =IF(RAW_DATA!F60="","",RAW_DATA!F60) -> -2452 | G20: =IF(RAW_DATA!G60="","",RAW_DATA!G60) -> -2720
A21: Net operating cash flow after tax — continuing (calculated) | B21: =IFERROR(B19+B20,"") -> 7972 | C21: =IFERROR(C19+C20,"") -> 7282 | D21: =IFERROR(D19+D20,"") -> 9426 | E21: =IFERROR(E19+E20,"") -> 8393 | F21: =IFERROR(F19+F20,"") -> 8461 | G21: =IFERROR(G19+G20,"") -> 8052 | H21: 2021–2023 Original: whole group (no discontinued split then).
A22: Net operating cash flow after tax (reported) | B22: =IF(RAW_DATA!B61="","",RAW_DATA!B61) -> 7972 | C22: =IF(RAW_DATA!C61="","",RAW_DATA!C61) -> 7282 | D22: =IF(RAW_DATA!D61="","",RAW_DATA!D61) -> 9426 | E22: =IF(RAW_DATA!E61="","",RAW_DATA!E61) | F22: =IF(RAW_DATA!F61="","",RAW_DATA!F61) -> 8461 | G22: =IF(RAW_DATA!G61="","",RAW_DATA!G61) -> 8052 | H22: As printed; 2023 Continuing not printed in sources accessed. Tested in S7.
A23: Net operating cash flow — discontinued | B23: =IF(RAW_DATA!B62="","",RAW_DATA!B62) -> 0 | C23: =IF(RAW_DATA!C62="","",RAW_DATA!C62) -> 0 | D23: =IF(RAW_DATA!D62="","",RAW_DATA!D62) -> 0 | E23: =IF(RAW_DATA!E62="","",RAW_DATA!E62) -> 1033 | F23: =IF(RAW_DATA!F62="","",RAW_DATA!F62) -> 1058 | G23: =IF(RAW_DATA!G62="","",RAW_DATA!G62) -> 298 | H23: 0 for 2021–2023 Original: no discontinued operations presented then.
A24: Net operating cash flow — total | B24: =IFERROR(B21+B23,"") -> 7972 | C24: =IFERROR(C21+C23,"") -> 7282 | D24: =IFERROR(D21+D23,"") -> 9426 | E24: =IFERROR(E21+E23,"") -> 9426 | F24: =IFERROR(F21+F23,"") -> 9519 | G24: =IFERROR(G21+G23,"") -> 8350
A26: B. Investing cash flow
A27: Net capital expenditure | B27: =IF(RAW_DATA!B64="","",RAW_DATA!B64) -> -1239 | C27: =IF(RAW_DATA!C64="","",RAW_DATA!C64) -> -1627 | D27: =IF(RAW_DATA!D64="","",RAW_DATA!D64) -> -1703 | E27: =IF(RAW_DATA!E64="","",RAW_DATA!E64) -> -1420 | F27: =IF(RAW_DATA!F64="","",RAW_DATA!F64) -> -1599 | G27: =IF(RAW_DATA!G64="","",RAW_DATA!G64) -> -1465 | H27: Per Unilever FCF reconciliation.
A28: Acquisitions (businesses and JV/associate investments) | B28: =IF(RAW_DATA!B71="","",RAW_DATA!B71) | C28: =IF(RAW_DATA!C71="","",RAW_DATA!C71) | D28: =IF(RAW_DATA!D71="","",RAW_DATA!D71) | E28: =IF(RAW_DATA!E71="","",RAW_DATA!E71) | F28: =IF(RAW_DATA!F71="","",RAW_DATA!F71) -> -734 | G28: =IF(RAW_DATA!G71="","",RAW_DATA!G71) -> -1674
A29: Disposals (businesses, JVs and associates) | B29: =IF(RAW_DATA!B72="","",RAW_DATA!B72) | C29: =IF(RAW_DATA!C72="","",RAW_DATA!C72) | D29: =IF(RAW_DATA!D72="","",RAW_DATA!D72) | E29: =IF(RAW_DATA!E72="","",RAW_DATA!E72) | F29: =IF(RAW_DATA!F72="","",RAW_DATA!F72) -> 910 | G29: =IF(RAW_DATA!G72="","",RAW_DATA!G72) -> 107
A30: Financial investments (sale/(purchase) of financial assets) | B30: =IF(RAW_DATA!B76="","",RAW_DATA!B76) | C30: =IF(RAW_DATA!C76="","",RAW_DATA!C76) | D30: =IF(RAW_DATA!D76="","",RAW_DATA!D76) | E30: =IF(RAW_DATA!E76="","",RAW_DATA!E76) | F30: =IF(RAW_DATA!F76="","",RAW_DATA!F76) -> 476 | G30: =IF(RAW_DATA!G76="","",RAW_DATA!G76) -> -85
A31: Interest received | B31: =IF(RAW_DATA!B77="","",RAW_DATA!B77) -> 148 | C31: =IF(RAW_DATA!C77="","",RAW_DATA!C77) -> 287 | D31: =IF(RAW_DATA!D77="","",RAW_DATA!D77) -> 267 | E31: =IF(RAW_DATA!E77="","",RAW_DATA!E77) | F31: =IF(RAW_DATA!F77="","",RAW_DATA!F77) -> 370 | G31: =IF(RAW_DATA!G77="","",RAW_DATA!G77) -> 352
A32: Other investing movements | B32: =IF(COUNT(RAW_DATA!B73,RAW_DATA!B74,RAW_DATA!B75)<3,"",RAW_DATA!B73+RAW_DATA!B74+RAW_DATA!B75) | C32: =IF(COUNT(RAW_DATA!C73,RAW_DATA!C74,RAW_DATA!C75)<3,"",RAW_DATA!C73+RAW_DATA!C74+RAW_DATA!C75) | D32: =IF(COUNT(RAW_DATA!D73,RAW_DATA!D74,RAW_DATA!D75)<3,"",RAW_DATA!D73+RAW_DATA!D74+RAW_DATA!D75) | E32: =IF(COUNT(RAW_DATA!E73,RAW_DATA!E74,RAW_DATA!E75)<3,"",RAW_DATA!E73+RAW_DATA!E74+RAW_DATA!E75) | F32: =IF(COUNT(RAW_DATA!F73,RAW_DATA!F74,RAW_DATA!F75)<3,"",RAW_DATA!F73+RAW_DATA!F74+RAW_DATA!F75) -> 154 | G32: =IF(COUNT(RAW_DATA!G73,RAW_DATA!G74,RAW_DATA!G75)<3,"",RAW_DATA!G73+RAW_DATA!G74+RAW_DATA!G75) -> 371 | H32: Derived: other non-current investments acquired + disposed + dividends from JVs/associates (reported lines in RAW_DATA).
A33: Memo: sum of investing lines | B33: =IFERROR(B27+B28+B29+B30+B31+B32,"") | C33: =IFERROR(C27+C28+C29+C30+C31+C32,"") | D33: =IFERROR(D27+D28+D29+D30+D31+D32,"") | E33: =IFERROR(E27+E28+E29+E30+E31+E32,"") | F33: =IFERROR(F27+F28+F29+F30+F31+F32,"") -> -423 | G33: =IFERROR(G27+G28+G29+G30+G31+G32,"") -> -2394 | H33: Should equal continuing investing cash flow (S8).
A34: Continuing investing cash flow | B34: =IF(RAW_DATA!B78="","",RAW_DATA!B78) -> -3246 | C34: =IF(RAW_DATA!C78="","",RAW_DATA!C78) -> 2453 | D34: =IF(RAW_DATA!D78="","",RAW_DATA!D78) -> -2294 | E34: =IF(RAW_DATA!E78="","",RAW_DATA!E78) -> -1411 | F34: =IF(RAW_DATA!F78="","",RAW_DATA!F78) -> -423 | G34: =IF(RAW_DATA!G78="","",RAW_DATA!G78) -> -2394
A35: Discontinued investing cash flow | B35: =IF(RAW_DATA!B79="","",RAW_DATA!B79) -> 0 | C35: =IF(RAW_DATA!C79="","",RAW_DATA!C79) -> 0 | D35: =IF(RAW_DATA!D79="","",RAW_DATA!D79) -> 0 | E35: =IF(RAW_DATA!E79="","",RAW_DATA!E79) -> -883 | F35: =IF(RAW_DATA!F79="","",RAW_DATA!F79) -> -202 | G35: =IF(RAW_DATA!G79="","",RAW_DATA!G79) -> -724
A36: Total investing cash flow | B36: =IF(RAW_DATA!B80="","",RAW_DATA!B80) -> -3246 | C36: =IF(RAW_DATA!C80="","",RAW_DATA!C80) -> 2453 | D36: =IF(RAW_DATA!D80="","",RAW_DATA!D80) -> -2294 | E36: =IF(RAW_DATA!E80="","",RAW_DATA!E80) -> -2294 | F36: =IF(RAW_DATA!F80="","",RAW_DATA!F80) -> -625 | G36: =IF(RAW_DATA!G80="","",RAW_DATA!G80) -> -3118 | H36: Total is used in the cash bridge; continuing ≠ total.
A38: C. Financing cash flow
A39: Dividends | B39: =IF(RAW_DATA!B82="","",RAW_DATA!B82) -> -4483 | C39: =IF(RAW_DATA!C82="","",RAW_DATA!C82) -> -4329 | D39: =IF(RAW_DATA!D82="","",RAW_DATA!D82) -> -4363 | E39: =IF(RAW_DATA!E82="","",RAW_DATA!E82) -> -4363 | F39: =IF(RAW_DATA!F82="","",RAW_DATA!F82) -> -4319 | G39: =IF(RAW_DATA!G82="","",RAW_DATA!G82) -> -4453
A40: Interest paid | B40: =IF(RAW_DATA!B83="","",RAW_DATA!B83) -> -488 | C40: =IF(RAW_DATA!C83="","",RAW_DATA!C83) -> -744 | D40: =IF(RAW_DATA!D83="","",RAW_DATA!D83) -> -899 | E40: =IF(RAW_DATA!E83="","",RAW_DATA!E83) -> -751 | F40: =IF(RAW_DATA!F83="","",RAW_DATA!F83) -> -929 | G40: =IF(RAW_DATA!G83="","",RAW_DATA!G83) -> -1018
A41: Short-term borrowing movement | B41: =IF(RAW_DATA!B84="","",RAW_DATA!B84) | C41: =IF(RAW_DATA!C84="","",RAW_DATA!C84) | D41: =IF(RAW_DATA!D84="","",RAW_DATA!D84) | E41: =IF(RAW_DATA!E84="","",RAW_DATA!E84) | F41: =IF(RAW_DATA!F84="","",RAW_DATA!F84) -> 575 | G41: =IF(RAW_DATA!G84="","",RAW_DATA!G84) -> -2228
A42: Additional financial liabilities | B42: =IF(RAW_DATA!B85="","",RAW_DATA!B85) | C42: =IF(RAW_DATA!C85="","",RAW_DATA!C85) | D42: =IF(RAW_DATA!D85="","",RAW_DATA!D85) | E42: =IF(RAW_DATA!E85="","",RAW_DATA!E85) | F42: =IF(RAW_DATA!F85="","",RAW_DATA!F85) -> 4234 | G42: =IF(RAW_DATA!G85="","",RAW_DATA!G85) -> 4278
A43: Repayment of financial liabilities | B43: =IF(RAW_DATA!B86="","",RAW_DATA!B86) | C43: =IF(RAW_DATA!C86="","",RAW_DATA!C86) | D43: =IF(RAW_DATA!D86="","",RAW_DATA!D86) | E43: =IF(RAW_DATA!E86="","",RAW_DATA!E86) | F43: =IF(RAW_DATA!F86="","",RAW_DATA!F86) -> -3846 | G43: =IF(RAW_DATA!G86="","",RAW_DATA!G86) -> -3547
...

Sheet WORKING_CAPITAL
A1: 06 WORKING_CAPITAL — BASIC MOVEMENTS ONLY (Step 3 builds DSO/DIO/DPO/CCC)
A2: € million. Movements compare year-end balances: 2022 vs 2021, 2023 vs 2022, 2024 vs 2023, 2025 vs 2024. 2021 needs 2020 balances (not in source).
A4: €m | B4: 2021 | C4: 2022 | D4: 2023 Original | E4: 2023 Continuing | F4: 2024 | G4: 2025 | H4: Notes
A5: Balances (from HISTORICAL_BS)
A6: Inventories | B6: =HISTORICAL_BS!B6 -> 4683 | C6: =HISTORICAL_BS!C6 -> 5931 | D6: =HISTORICAL_BS!D6 -> 5119 | F6: =HISTORICAL_BS!F6 -> 5177 | G6: =HISTORICAL_BS!G6 -> 4043
A7: Trade receivables | B7: =HISTORICAL_BS!B7 -> 3582 | C7: =HISTORICAL_BS!C7 -> 4544 | D7: =HISTORICAL_BS!D7 -> 4023 | F7: =HISTORICAL_BS!F7 -> 4227 | G7: =HISTORICAL_BS!G7 -> 4852
A8: Trade payables | B8: =HISTORICAL_BS!B26 -> 8896 | C8: =HISTORICAL_BS!C26 -> 11100 | D8: =HISTORICAL_BS!D26 -> 10355 | F8: =HISTORICAL_BS!F26 -> 10258 | G8: =HISTORICAL_BS!G26 -> 10994
A10: Movements
A11: Δ Inventory | C11: =IFERROR(C6-B6,"") -> 1248 | D11: =IFERROR(D6-C6,"") -> -812 | F11: =IFERROR(F6-D6,"") -> 58 | G11: =IFERROR(G6-F6,"") -> -1134
A12: Δ Receivables (trade) | C12: =IFERROR(C7-B7,"") -> 962 | D12: =IFERROR(D7-C7,"") -> -521 | F12: =IFERROR(F7-D7,"") -> 204 | G12: =IFERROR(G7-F7,"") -> 625
A13: Δ Payables (trade) | C13: =IFERROR(C8-B8,"") -> 2204 | D13: =IFERROR(D8-C8,"") -> -745 | F13: =IFERROR(F8-D8,"") -> -97 | G13: =IFERROR(G8-F8,"") -> 736
A15: Cash impact (sign convention: positive = cash released)
A16: Inventory cash impact (−Δ inventory) | C16: =IFERROR(-C11,"") -> -1248 | D16: =IFERROR(-D11,"") -> 812 | F16: =IFERROR(-F11,"") -> -58 | G16: =IFERROR(-G11,"") -> 1134
A17: Receivables cash impact (−Δ receivables) | C17: =IFERROR(-C12,"") -> -962 | D17: =IFERROR(-D12,"") -> 521 | F17: =IFERROR(-F12,"") -> -204 | G17: =IFERROR(-G12,"") -> -625
A18: Payables cash impact (+Δ payables) | C18: =IFERROR(C13,"") -> 2204 | D18: =IFERROR(D13,"") -> -745 | F18: =IFERROR(F13,"") -> -97 | G18: =IFERROR(G13,"") -> 736
A19: Simplified working-capital cash impact | C19: =IFERROR(C16+C17+C18,"") -> -6 | D19: =IFERROR(D16+D17+D18,"") -> 588 | F19: =IFERROR(F16+F17+F18,"") -> -359 | G19: =IFERROR(G16+G17+G18,"") -> 1245
A20: Memo: change in working capital per cash-flow statement | B20: =HISTORICAL_CF!B12 | C20: =HISTORICAL_CF!C12 | D20: =HISTORICAL_CF!D12 | E20: =HISTORICAL_CF!E12 -> 753 | F20: =HISTORICAL_CF!F12 -> -188 | G20: =HISTORICAL_CF!G12 -> 116 | H20: Reported cash effect (continuing), available 2023 Continuing–2025. Differs from the simplified balance-sheet impact above — see notes.
A22: Interpretation notes
A23: • Balance-sheet movements are not cash flows: they include FX translation, acquisitions/disposals and reclassifications. The cash-flow statement figure is the reported cash effect.
A24: • 2025 vs 2024: the Ice Cream demerger completed in December 2025, so 2025 year-end balances exclude Ice Cream while 2024 balances were reported before it. Part of the 2025 movement is a demerger effect, not trading cash.
A25: • Only trade receivables and trade payables are used here, as specified. Other receivables, accruals and other operating liabilities are on HISTORICAL_BS.
A26: • DSO, DIO, DPO, CCC, cash-release calculations and sensitivities belong to Step 3.

Sheet HISTORICAL_CHECKS
A1: 07 HISTORICAL_CHECKS — RECONCILIATIONS AND AUTOMATIC STATUS FLAGS
A2: Every status is a formula. N/A = at least one input for that period is Unavailable in the source. Differences in € million.
A3: Tolerance (€m) | B3: 1 | C3: Reported figures are rounded to €1m, so a €1m difference is rounding (e.g. 2025 PBT 8,693 − tax 2,481 = 6,212 vs reported 6,213). A 0.1 tolerance would flag rounding as ERROR.
A5: Summary
A6: Core checks with status PASS | B6: =(H14="PASS")*1+(H16="PASS")*1+(H18="PASS")*1+(H20="PASS")*1+(H22="PASS")*1+(H24="PASS")*1 -> 6
A7: Core checks with status ERROR | B7: =(H14="ERROR")*1+(H16="ERROR")*1+(H18="ERROR")*1+(H20="ERROR")*1+(H22="ERROR")*1+(H24="ERROR")*1 -> 0
A8: Core checks fully N/A (not yet testable — source data missing) | B8: =(H14="N/A")*1+(H16="N/A")*1+(H18="N/A")*1+(H20="N/A")*1+(H22="N/A")*1+(H24="N/A")*1 -> 0
A9: Period-level ERROR flags (core + supplementary) | B9: =COUNTIF(B15:G15,"ERROR")+COUNTIF(B17:G17,"ERROR")+COUNTIF(B19:G19,"ERROR")+COUNTIF(B21:G21,"ERROR")+COUNTIF(B23:G23,"ERROR")+COUNTIF(B25:G25,"ERROR")+COUNTIF(B30:G30,"ERROR")+COUNTIF(B32:G32,"ERROR")+COUNTIF(B34:G34,"ERROR")+COUNTIF(B36:G36,"ERROR")+COUNTIF(B38:G38,"ERROR")+COUNTIF(B40:G40,"ERROR")+COUNTIF(B42:G42,"ERROR")+COUNTIF(B44:G44,"ERROR")+COUNTIF(B46:G46,"ERROR") -> 0
A10: STEP 2 STATUS | B10: =IF(B7+B9>0,"NOT COMPLETE — resolve ERROR flags",IF(B8>0,"BUILT — "&B8&" of 6 core checks awaiting source data","COMPLETE — all core checks PASS")) -> COMPLETE — all core checks PASS
A12: Core checks (Step 2 specification)
A13: Check | B13: 2021 | C13: 2022 | D13: 2023 Original | E13: 2023 Continuing | F13: 2024 | G13: 2025 | H13: Status | I13: Periods tested | J13: What it tests / why N/A
A14: Check 1 — PBT: operating profit − net finance costs + hyperinflation + JV/associate share + other income − PBT | B14: =IF(COUNT(HISTORICAL_IS!B8,HISTORICAL_IS!B9,HISTORICAL_IS!B10,HISTORICAL_IS!B11,HISTORICAL_IS!B12,HISTORICAL_IS!B13)<6,"N/A",HISTORICAL_IS!B8-HISTORICAL_IS!B9+HISTORICAL_IS!B10+HISTORICAL_IS!B11+HISTORICAL_IS!B12-HISTORICAL_IS!B13) -> 0 | C14: =IF(COUNT(HISTORICAL_IS!C8,HISTORICAL_IS!C9,HISTORICAL_IS!C10,HISTORICAL_IS!C11,HISTORICAL_IS!C12,HISTORICAL_IS!C13)<6,"N/A",HISTORICAL_IS!C8-HISTORICAL_IS!C9+HISTORICAL_IS!C10+HISTORICAL_IS!C11+HISTORICAL_IS!C12-HISTORICAL_IS!C13) -> 0 | D14: =IF(COUNT(HISTORICAL_IS!D8,HISTORICAL_IS!D9,HISTORICAL_IS!D10,HISTORICAL_IS!D11,HISTORICAL_IS!D12,HISTORICAL_IS!D13)<6,"N/A",HISTORICAL_IS!D8-HISTORICAL_IS!D9+HISTORICAL_IS!D10+HISTORICAL_IS!D11+HISTORICAL_IS!D12-HISTORICAL_IS!D13) -> 0 | E14: =IF(COUNT(HISTORICAL_IS!E8,HISTORICAL_IS!E9,HISTORICAL_IS!E10,HISTORICAL_IS!E11,HISTORICAL_IS!E12,HISTORICAL_IS!E13)<6,"N/A",HISTORICAL_IS!E8-HISTORICAL_IS!E9+HISTORICAL_IS!E10+HISTORICAL_IS!E11+HISTORICAL_IS!E12-HISTORICAL_IS!E13) -> 0 | F14: =IF(COUNT(HISTORICAL_IS!F8,HISTORICAL_IS!F9,HISTORICAL_IS!F10,HISTORICAL_IS!F11,HISTORICAL_IS!F12,HISTORICAL_IS!F13)<6,"N/A",HISTORICAL_IS!F8-HISTORICAL_IS!F9+HISTORICAL_IS!F10+HISTORICAL_IS!F11+HISTORICAL_IS!F12-HISTORICAL_IS!F13) -> 0 | G14: =IF(COUNT(HISTORICAL_IS!G8,HISTORICAL_IS!G9,HISTORICAL_IS!G10,HISTORICAL_IS!G11,HISTORICAL_IS!G12,HISTORICAL_IS!G13)<6,"N/A",HISTORICAL_IS!G8-HISTORICAL_IS!G9+HISTORICAL_IS!G10+HISTORICAL_IS!G11+HISTORICAL_IS!G12-HISTORICAL_IS!G13) -> 1 | H14: =IF(COUNTIF(B15:G15,"ERROR")>0,"ERROR",IF(COUNTIF(B15:G15,"PASS")>0,"PASS","N/A")) -> PASS | I14: =COUNTIF(B15:G15,"PASS")+COUNTIF(B15:G15,"ERROR")&" of 6" -> 6 of 6 | J14: Unilever's reported structure between operating profit and PBT (all five lines).
A15: status | B15: =IF(B14="N/A","N/A",IF(ABS(B14)<=$B$3,"PASS","ERROR")) -> PASS | C15: =IF(C14="N/A","N/A",IF(ABS(C14)<=$B$3,"PASS","ERROR")) -> PASS | D15: =IF(D14="N/A","N/A",IF(ABS(D14)<=$B$3,"PASS","ERROR")) -> PASS | E15: =IF(E14="N/A","N/A",IF(ABS(E14)<=$B$3,"PASS","ERROR")) -> PASS | F15: =IF(F14="N/A","N/A",IF(ABS(F14)<=$B$3,"PASS","ERROR")) -> PASS | G15: =IF(G14="N/A","N/A",IF(ABS(G14)<=$B$3,"PASS","ERROR")) -> PASS
A16: Check 2 — Net income: PBT − tax − net profit | B16: =IF(COUNT(HISTORICAL_IS!B13,HISTORICAL_IS!B14,HISTORICAL_IS!B15)<3,"N/A",HISTORICAL_IS!B13-HISTORICAL_IS!B14-HISTORICAL_IS!B15) -> 0 | C16: =IF(COUNT(HISTORICAL_IS!C13,HISTORICAL_IS!C14,HISTORICAL_IS!C15)<3,"N/A",HISTORICAL_IS!C13-HISTORICAL_IS!C14-HISTORICAL_IS!C15) -> 0 | D16: =IF(COUNT(HISTORICAL_IS!D13,HISTORICAL_IS!D14,HISTORICAL_IS!D15)<3,"N/A",HISTORICAL_IS!D13-HISTORICAL_IS!D14-HISTORICAL_IS!D15) -> 0 | E16: =IF(COUNT(HISTORICAL_IS!E13,HISTORICAL_IS!E14,HISTORICAL_IS!E15)<3,"N/A",HISTORICAL_IS!E13-HISTORICAL_IS!E14-HISTORICAL_IS!E15) -> 0 | F16: =IF(COUNT(HISTORICAL_IS!F13,HISTORICAL_IS!F14,HISTORICAL_IS!F15)<3,"N/A",HISTORICAL_IS!F13-HISTORICAL_IS!F14-HISTORICAL_IS!F15) -> 0 | G16: =IF(COUNT(HISTORICAL_IS!G13,HISTORICAL_IS!G14,HISTORICAL_IS!G15)<3,"N/A",HISTORICAL_IS!G13-HISTORICAL_IS!G14-HISTORICAL_IS!G15) -> -1 | H16: =IF(COUNTIF(B17:G17,"ERROR")>0,"ERROR",IF(COUNTIF(B17:G17,"PASS")>0,"PASS","N/A")) -> PASS | I16: =COUNTIF(B17:G17,"PASS")+COUNTIF(B17:G17,"ERROR")&" of 6" -> 6 of 6
A17: status | B17: =IF(B16="N/A","N/A",IF(ABS(B16)<=$B$3,"PASS","ERROR")) -> PASS | C17: =IF(C16="N/A","N/A",IF(ABS(C16)<=$B$3,"PASS","ERROR")) -> PASS | D17: =IF(D16="N/A","N/A",IF(ABS(D16)<=$B$3,"PASS","ERROR")) -> PASS | E17: =IF(E16="N/A","N/A",IF(ABS(E16)<=$B$3,"PASS","ERROR")) -> PASS | F17: =IF(F16="N/A","N/A",IF(ABS(F16)<=$B$3,"PASS","ERROR")) -> PASS | G17: =IF(G16="N/A","N/A",IF(ABS(G16)<=$B$3,"PASS","ERROR")) -> PASS
A18: Check 3 — Financial liabilities: current + non-current − reported total | B18: =IF(COUNT(HISTORICAL_BS!B49,HISTORICAL_BS!B50)<2,"N/A",HISTORICAL_BS!B49-HISTORICAL_BS!B50) -> 0 | C18: =IF(COUNT(HISTORICAL_BS!C49,HISTORICAL_BS!C50)<2,"N/A",HISTORICAL_BS!C49-HISTORICAL_BS!C50) -> 0 | D18: =IF(COUNT(HISTORICAL_BS!D49,HISTORICAL_BS!D50)<2,"N/A",HISTORICAL_BS!D49-HISTORICAL_BS!D50) -> 0 | F18: =IF(COUNT(HISTORICAL_BS!F49,HISTORICAL_BS!F50)<2,"N/A",HISTORICAL_BS!F49-HISTORICAL_BS!F50) -> 0 | G18: =IF(COUNT(HISTORICAL_BS!G49,HISTORICAL_BS!G50)<2,"N/A",HISTORICAL_BS!G49-HISTORICAL_BS!G50) -> 0 | H18: =IF(COUNTIF(B19:G19,"ERROR")>0,"ERROR",IF(COUNTIF(B19:G19,"PASS")>0,"PASS","N/A")) -> PASS | I18: =COUNTIF(B19:G19,"PASS")+COUNTIF(B19:G19,"ERROR")&" of 5" -> 5 of 5
A19: status | B19: =IF(B18="N/A","N/A",IF(ABS(B18)<=$B$3,"PASS","ERROR")) -> PASS | C19: =IF(C18="N/A","N/A",IF(ABS(C18)<=$B$3,"PASS","ERROR")) -> PASS | D19: =IF(D18="N/A","N/A",IF(ABS(D18)<=$B$3,"PASS","ERROR")) -> PASS | F19: =IF(F18="N/A","N/A",IF(ABS(F18)<=$B$3,"PASS","ERROR")) -> PASS | G19: =IF(G18="N/A","N/A",IF(ABS(G18)<=$B$3,"PASS","ERROR")) -> PASS
A20: Check 4 — FCF: calculated − reported | B20: =IF(COUNT(HISTORICAL_CF!B57,HISTORICAL_CF!B58)<2,"N/A",HISTORICAL_CF!B57-HISTORICAL_CF!B58) -> 0 | C20: =IF(COUNT(HISTORICAL_CF!C57,HISTORICAL_CF!C58)<2,"N/A",HISTORICAL_CF!C57-HISTORICAL_CF!C58) -> 0 | D20: =IF(COUNT(HISTORICAL_CF!D57,HISTORICAL_CF!D58)<2,"N/A",HISTORICAL_CF!D57-HISTORICAL_CF!D58) -> 0 | E20: =IF(COUNT(HISTORICAL_CF!E57,HISTORICAL_CF!E58)<2,"N/A",HISTORICAL_CF!E57-HISTORICAL_CF!E58) -> 0 | F20: =IF(COUNT(HISTORICAL_CF!F57,HISTORICAL_CF!F58)<2,"N/A",HISTORICAL_CF!F57-HISTORICAL_CF!F58) -> -1 | G20: =IF(COUNT(HISTORICAL_CF!G57,HISTORICAL_CF!G58)<2,"N/A",HISTORICAL_CF!G57-HISTORICAL_CF!G58) -> 0 | H20: =IF(COUNTIF(B21:G21,"ERROR")>0,"ERROR",IF(COUNTIF(B21:G21,"PASS")>0,"PASS","N/A")) -> PASS | I20: =COUNTIF(B21:G21,"PASS")+COUNTIF(B21:G21,"ERROR")&" of 6" -> 6 of 6
A21: status | B21: =IF(B20="N/A","N/A",IF(ABS(B20)<=$B$3,"PASS","ERROR")) -> PASS | C21: =IF(C20="N/A","N/A",IF(ABS(C20)<=$B$3,"PASS","ERROR")) -> PASS | D21: =IF(D20="N/A","N/A",IF(ABS(D20)<=$B$3,"PASS","ERROR")) -> PASS | E21: =IF(E20="N/A","N/A",IF(ABS(E20)<=$B$3,"PASS","ERROR")) -> PASS | F21: =IF(F20="N/A","N/A",IF(ABS(F20)<=$B$3,"PASS","ERROR")) -> PASS | G21: =IF(G20="N/A","N/A",IF(ABS(G20)<=$B$3,"PASS","ERROR")) -> PASS
A22: Check 5 — Net debt: model − reported | B22: =IF(COUNT(HISTORICAL_BS!B59,HISTORICAL_BS!B60)<2,"N/A",HISTORICAL_BS!B59-HISTORICAL_BS!B60) -> 0 | C22: =IF(COUNT(HISTORICAL_BS!C59,HISTORICAL_BS!C60)<2,"N/A",HISTORICAL_BS!C59-HISTORICAL_BS!C60) -> 0 | D22: =IF(COUNT(HISTORICAL_BS!D59,HISTORICAL_BS!D60)<2,"N/A",HISTORICAL_BS!D59-HISTORICAL_BS!D60) -> 0 | F22: =IF(COUNT(HISTORICAL_BS!F59,HISTORICAL_BS!F60)<2,"N/A",HISTORICAL_BS!F59-HISTORICAL_BS!F60) -> 0 | G22: =IF(COUNT(HISTORICAL_BS!G59,HISTORICAL_BS!G60)<2,"N/A",HISTORICAL_BS!G59-HISTORICAL_BS!G60) -> 0 | H22: =IF(COUNTIF(B23:G23,"ERROR")>0,"ERROR",IF(COUNTIF(B23:G23,"PASS")>0,"PASS","N/A")) -> PASS | I22: =COUNTIF(B23:G23,"PASS")+COUNTIF(B23:G23,"ERROR")&" of 5" -> 5 of 5 | J22: Total financial liabilities − BS cash − other current financial assets − non-current derivative assets.
A23: status | B23: =IF(B22="N/A","N/A",IF(ABS(B22)<=$B$3,"PASS","ERROR")) -> PASS | C23: =IF(C22="N/A","N/A",IF(ABS(C22)<=$B$3,"PASS","ERROR")) -> PASS | D23: =IF(D22="N/A","N/A",IF(ABS(D22)<=$B$3,"PASS","ERROR")) -> PASS | F23: =IF(F22="N/A","N/A",IF(ABS(F22)<=$B$3,"PASS","ERROR")) -> PASS | G23: =IF(G22="N/A","N/A",IF(ABS(G22)<=$B$3,"PASS","ERROR")) -> PASS
A24: Check 6 — Cash bridge: opening + operating + investing + financing + FX − closing | B24: =IF(COUNT(HISTORICAL_CF!B67,HISTORICAL_CF!B68)<2,"N/A",HISTORICAL_CF!B67-HISTORICAL_CF!B68) -> 0 | C24: =IF(COUNT(HISTORICAL_CF!C67,HISTORICAL_CF!C68)<2,"N/A",HISTORICAL_CF!C67-HISTORICAL_CF!C68) -> 0 | D24: =IF(COUNT(HISTORICAL_CF!D67,HISTORICAL_CF!D68)<2,"N/A",HISTORICAL_CF!D67-HISTORICAL_CF!D68) -> 0 | E24: =IF(COUNT(HISTORICAL_CF!E67,HISTORICAL_CF!E68)<2,"N/A",HISTORICAL_CF!E67-HISTORICAL_CF!E68) -> 0 | F24: =IF(COUNT(HISTORICAL_CF!F67,HISTORICAL_CF!F68)<2,"N/A",HISTORICAL_CF!F67-HISTORICAL_CF!F68) -> 0 | G24: =IF(COUNT(HISTORICAL_CF!G67,HISTORICAL_CF!G68)<2,"N/A",HISTORICAL_CF!G67-HISTORICAL_CF!G68) -> 0 | H24: =IF(COUNTIF(B25:G25,"ERROR")>0,"ERROR",IF(COUNTIF(B25:G25,"PASS")>0,"PASS","N/A")) -> PASS | I24: =COUNTIF(B25:G25,"PASS")+COUNTIF(B25:G25,"ERROR")&" of 6" -> 6 of 6 | J24: Cash-flow-statement cash throughout; balance-sheet cash is never forced in.
A25: status | B25: =IF(B24="N/A","N/A",IF(ABS(B24)<=$B$3,"PASS","ERROR")) -> PASS | C25: =IF(C24="N/A","N/A",IF(ABS(C24)<=$B$3,"PASS","ERROR")) -> PASS | D25: =IF(D24="N/A","N/A",IF(ABS(D24)<=$B$3,"PASS","ERROR")) -> PASS | E25: =IF(E24="N/A","N/A",IF(ABS(E24)<=$B$3,"PASS","ERROR")) -> PASS | F25: =IF(F24="N/A","N/A",IF(ABS(F24)<=$B$3,"PASS","ERROR")) -> PASS | G25: =IF(G24="N/A","N/A",IF(ABS(G24)<=$B$3,"PASS","ERROR")) -> PASS
A27: Supplementary checks (not required by the spec; they locate problems when a core check fails)
A28: Check | B28: 2021 | C28: 2022 | D28: 2023 Original | E28: 2023 Continuing | F28: 2024 | G28: 2025 | H28: Status | I28: Periods tested | J28: What it tests / why N/A
A29: S1 — Cash definitions: CF cash + overdrafts + held-for-sale adjustment − balance-sheet cash | B29: =IF(COUNT(HISTORICAL_BS!B18,HISTORICAL_BS!B19,HISTORICAL_BS!B20,HISTORICAL_BS!B17)<4,"N/A",HISTORICAL_BS!B18+HISTORICAL_BS!B19+HISTORICAL_BS!B20-HISTORICAL_BS!B17) -> 0 | C29: =IF(COUNT(HISTORICAL_BS!C18,HISTORICAL_BS!C19,HISTORICAL_BS!C20,HISTORICAL_BS!C17)<4,"N/A",HISTORICAL_BS!C18+HISTORICAL_BS!C19+HISTORICAL_BS!C20-HISTORICAL_BS!C17) -> 0 | D29: =IF(COUNT(HISTORICAL_BS!D18,HISTORICAL_BS!D19,HISTORICAL_BS!D20,HISTORICAL_BS!D17)<4,"N/A",HISTORICAL_BS!D18+HISTORICAL_BS!D19+HISTORICAL_BS!D20-HISTORICAL_BS!D17) -> 0 | F29: =IF(COUNT(HISTORICAL_BS!F18,HISTORICAL_BS!F19,HISTORICAL_BS!F20,HISTORICAL_BS!F17)<4,"N/A",HISTORICAL_BS!F18+HISTORICAL_BS!F19+HISTORICAL_BS!F20-HISTORICAL_BS!F17) -> 0 | G29: =IF(COUNT(HISTORICAL_BS!G18,HISTORICAL_BS!G19,HISTORICAL_BS!G20,HISTORICAL_BS!G17)<4,"N/A",HISTORICAL_BS!G18+HISTORICAL_BS!G19+HISTORICAL_BS!G20-HISTORICAL_BS!G17) -> 0 | H29: =IF(COUNTIF(B30:G30,"ERROR")>0,"ERROR",IF(COUNTIF(B30:G30,"PASS")>0,"PASS","N/A")) -> PASS | I29: =COUNTIF(B30:G30,"PASS")+COUNTIF(B30:G30,"ERROR")&" of 5" -> 5 of 5 | J29: Held-for-sale adjustment carries the sign printed by Unilever (brackets = deduction).
A30: status | B30: =IF(B29="N/A","N/A",IF(ABS(B29)<=$B$3,"PASS","ERROR")) -> PASS | C30: =IF(C29="N/A","N/A",IF(ABS(C29)<=$B$3,"PASS","ERROR")) -> PASS | D30: =IF(D29="N/A","N/A",IF(ABS(D29)<=$B$3,"PASS","ERROR")) -> PASS | F30: =IF(F29="N/A","N/A",IF(ABS(F29)<=$B$3,"PASS","ERROR")) -> PASS | G30: =IF(G29="N/A","N/A",IF(ABS(G29)<=$B$3,"PASS","ERROR")) -> PASS
A31: S2 — Current financial-liability categories − reported current total | B31: =IF(COUNT(HISTORICAL_BS!B38,HISTORICAL_BS!B39)<2,"N/A",HISTORICAL_BS!B38-HISTORICAL_BS!B39) -> N/A | C31: =IF(COUNT(HISTORICAL_BS!C38,HISTORICAL_BS!C39)<2,"N/A",HISTORICAL_BS!C38-HISTORICAL_BS!C39) -> N/A | D31: =IF(COUNT(HISTORICAL_BS!D38,HISTORICAL_BS!D39)<2,"N/A",HISTORICAL_BS!D38-HISTORICAL_BS!D39) -> N/A | F31: =IF(COUNT(HISTORICAL_BS!F38,HISTORICAL_BS!F39)<2,"N/A",HISTORICAL_BS!F38-HISTORICAL_BS!F39) -> N/A | G31: =IF(COUNT(HISTORICAL_BS!G38,HISTORICAL_BS!G39)<2,"N/A",HISTORICAL_BS!G38-HISTORICAL_BS!G39) -> N/A | H31: =IF(COUNTIF(B32:G32,"ERROR")>0,"ERROR",IF(COUNTIF(B32:G32,"PASS")>0,"PASS","N/A")) -> N/A | I31: =COUNTIF(B32:G32,"PASS")+COUNTIF(B32:G32,"ERROR")&" of 5" -> 0 of 5
A32: status | B32: =IF(B31="N/A","N/A",IF(ABS(B31)<=$B$3,"PASS","ERROR")) -> N/A | C32: =IF(C31="N/A","N/A",IF(ABS(C31)<=$B$3,"PASS","ERROR")) -> N/A | D32: =IF(D31="N/A","N/A",IF(ABS(D31)<=$B$3,"PASS","ERROR")) -> N/A | F32: =IF(F31="N/A","N/A",IF(ABS(F31)<=$B$3,"PASS","ERROR")) -> N/A | G32: =IF(G31="N/A","N/A",IF(ABS(G31)<=$B$3,"PASS","ERROR")) -> N/A
A33: S3 — Non-current financial-liability categories − reported non-current total | B33: =IF(COUNT(HISTORICAL_BS!B46,HISTORICAL_BS!B47)<2,"N/A",HISTORICAL_BS!B46-HISTORICAL_BS!B47) -> N/A | C33: =IF(COUNT(HISTORICAL_BS!C46,HISTORICAL_BS!C47)<2,"N/A",HISTORICAL_BS!C46-HISTORICAL_BS!C47) -> N/A | D33: =IF(COUNT(HISTORICAL_BS!D46,HISTORICAL_BS!D47)<2,"N/A",HISTORICAL_BS!D46-HISTORICAL_BS!D47) -> N/A | F33: =IF(COUNT(HISTORICAL_BS!F46,HISTORICAL_BS!F47)<2,"N/A",HISTORICAL_BS!F46-HISTORICAL_BS!F47) -> N/A | G33: =IF(COUNT(HISTORICAL_BS!G46,HISTORICAL_BS!G47)<2,"N/A",HISTORICAL_BS!G46-HISTORICAL_BS!G47) -> N/A | H33: =IF(COUNTIF(B34:G34,"ERROR")>0,"ERROR",IF(COUNTIF(B34:G34,"PASS")>0,"PASS","N/A")) -> N/A | I33: =COUNTIF(B34:G34,"PASS")+COUNTIF(B34:G34,"ERROR")&" of 5" -> 0 of 5
A34: status | B34: =IF(B33="N/A","N/A",IF(ABS(B33)<=$B$3,"PASS","ERROR")) -> N/A | C34: =IF(C33="N/A","N/A",IF(ABS(C33)<=$B$3,"PASS","ERROR")) -> N/A | D34: =IF(D33="N/A","N/A",IF(ABS(D33)<=$B$3,"PASS","ERROR")) -> N/A | F34: =IF(F33="N/A","N/A",IF(ABS(F33)<=$B$3,"PASS","ERROR")) -> N/A | G34: =IF(G33="N/A","N/A",IF(ABS(G33)<=$B$3,"PASS","ERROR")) -> N/A
